Workbook

Sheet 使い方
A1: ■ このファイルの使い方
A2: 1. 『アタックリスト』の黄色の列（担当者〜メモ）が入力欄です。ステータスはプルダウンから選んでください。
A3: 2. 優先度：A＝規格商品がなく中規模で集客課題が見える／B＝適合度が中くらい／C＝情報不足、または他FC加盟済み
A4: 3. 次回アクション日が今日以前で、まだ完了していない行は赤く表示されます。
A5: 4. 見送り・対象外にした行はグレー表示になります。
A6: 5. 『サマリー』は県別・ステータス別の件数を自動で集計します（リスト下に追記した行も、200行先まで集計されます）。
A8: ■ データについての注意
A9: ・会社情報は2026年10月時点のWeb検索結果をもとにしています。社名・規模・FC加盟状況は、アプローチ前に公式サイトで確認してください。
A10: ・確認できなかった項目は空欄のままにしています（推測では埋めていません）。
A11: ・LIFE X既存加盟店は除外済みです（『除外_既存加盟店』シート）。

Sheet アタックリスト
A1: No | B1: 優先度 | C1: 都道府県 | D1: 市区町村 | E1: 会社名 | F1: 公式サイト | G1: 主力事業・商品 | H1: 規模（確認できた範囲） | I1: 競合FC加盟状況 | J1: LIFE Xが刺さる理由 | K1: 根拠URL | L1: 担当者 | M1: ステータス | N1: 初回接触日 | O1: 次回アクション日 | P1: 次回アクション内容 | Q1: 先方キーマン | R1: メモ
A2: 1 | B2: A | C2: 神奈川県 | D2: 厚木市 | E2: 株式会社厚木地所 | G2: 県央エリアの不動産売買・仲介・自社分譲。減震パッキン工法の「エコファミリー」住宅を建築 | H2: 住宅建設31期で累計526棟（年平均約17棟と算出） | J2: 「良質な住宅を低価格で」を掲げ不動産集客の導線を持つ一方、高性能な規格商品は見当たらず、LIFE Xで商品力を補える | K2: https://tsukulink.net/kanagawa/city_142123/764560 | M2: 未着手
A3: 2 | B3: A | C3: 神奈川県 | D3: 相模原市 | E3: 相陽建設株式会社 | G3: 1970年創業の総合建設。注文住宅中心で主力は外断熱・二重通気の「ソーラーサーキットの家」、自然素材リフォームも | H3: 正社員規模推定33名（SalesNow） | I3: ソーラーサーキット工法採用（工法ネットワーク。住宅FCかは未確認） | J3: 高性能注文住宅が主体で、低価格帯の規格商品を持っている様子がなく、LIFE Xの1,890万円〜規格住宅で一次取得層を取り込める | K3: https://salesnow.jp/db/companies/jcbpca0vj3wg63wd ; https://crexgroup.com/ja/home-building/region/sagamihara-construction-company-list/ | M3: 未着手
A4: 3 | B4: A | C4: 神奈川県 | D4: 茅ヶ崎市 | E4: 大勝建設株式会社 | F4: https://www.daikatsu.plus/ | G4: 創業110年超の建設・住宅・不動産会社。自由設計・全棟長期優良住宅・耐震等級3の注文住宅（＋DAIKATSU） | H4: 資本金2,500万円、創業114年（Yahoo不動産・会社情報） | J4: 自由設計の注文が主体で規格商品が見えず、耐震等級3の土台がある分、断熱等級6・太陽光標準の規格商品を足しやすい | K4: https://realestate.yahoo.co.jp/company/used/bc00023294/ ; https://www.daikatsu.plus/ | M4: 未着手
A5: 4 | B5: B | C5: 神奈川県 | D5: 平塚市 | E5: 株式会社阿部建業 | G5: 創業55年超、湘南西部（平塚・茅ヶ崎・伊勢原・秦野等）の注文住宅・リフォーム・不動産。「コミコミ注文住宅」「平屋の家ふらっと君16」 | J5: パッケージ商品はあるが断熱等級4が標準のため、等級6・太陽光標準の規格住宅に上位互換として置き換える提案ができる | K5: https://compalyze.co.jp/company/6021001036109 ; https://www.e-mansion.co.jp/bbs/thread/11219/ | M5: 未着手
A6: 5 | B6: B | C6: 神奈川県 | D6: 横浜市金沢区 | E6: 大栄建設株式会社 | G6: 金沢区で地域密着35年。土地探し・資金計画から注文住宅、リフォーム、耐震補強まで | J6: リフォーム寄りの小規模工務店のようで、新築集客の目玉になる規格商品が無い | K6: https://www.biz.ne.jp/company/daiei1101/ | M6: 未着手
A7: 6 | B7: B | C7: 神奈川県 | D7: 茅ヶ崎市 | E7: 株式会社加賀妻工務店 | F7: http://www.kagatuma.co.jp/ | G7: 約50年の地域工務店。国産材・自然素材の木造住宅、大型リノベーション、耐震工事、不動産 | H7: 正社員規模推定18名（SalesNow） | J7: 高価格帯の自然素材注文住宅やリノベーションが主体で、若年層向けの規格商品が無い | K7: https://www.biz.ne.jp/corporation/26676/ ; https://salesnow.jp/db/companies/jcbpyxufanr08sdk | M7: 未着手
A8: 7 | B8: B | C8: 神奈川県 | D8: 藤沢市 | E8: サンキホーム株式会社 | F8: https://www.sankihome.co.jp/ | G8: 藤沢・茅ヶ崎・鎌倉・逗子の湘南エリアで天然素材の健康住宅（「緑の柱」採用）を手がける | J8: 天然素材の注文住宅が主体で、ローコスト・規格の品ぞろえが確認できない | K8: https://www.city.fujisawa.kanagawa.jp/documents/33414/r5jisseki_sankihome.pdf ; https://www.sankihome.co.jp/ | M8: 未着手
A9: 8 | B9: C | C9: 神奈川県 | E9: 神奈川エコハウス株式会社 | G9: 1972年設立。「健康と住環境」を重視した注文住宅。神奈川県産桧、基礎断熱、エアサイクル工法。港北の無添加住宅モデルハウス | I9: 無添加住宅のモデルハウスを運営との情報あり（無添加住宅ネットワークへの加盟を要確認） | J9: 健康住宅の高単価注文が軸で、性能を前に出した低価格規格帯が無い | K9: https://www.e-mansion.co.jp/bbs/thread/11729/ ; https://compalyze.co.jp/company/8021002003659 | M9: 未着手
A10: 9 | B10: C | C10: 神奈川県 | E10: 石原工務店 | F10: https://www.ishihara396.com/ | G10: 湘南エリア中心にシンプルで高性能な家づくり | J10: シンプル・高性能という方向性がLIFE Xと近く、商品化を後押しできる余地がある | K10: https://www.ishihara396.com/useful/3253/ | M10: 未着手
A11: 10 | B11: C | C11: 神奈川県 | E11: かつ七興産 | G11: 湘南の高性能注文住宅。HEAT20 G2標準、G3対応 | H11: 年間100棟以上（比較サイト記載） | J11: 棟数が対象の上限を超えるうえ性能も既に高く、適合度は低い | K11: https://local-time.jp/shonan-komuten/ | M11: 未着手
A12: 11 | B12: C | C12: 神奈川県 | D12: 厚木市 | E12: 民家工房常栄 | G12: 国産材・地元神奈川の木を使った自然派住宅 | J12: 自然派の注文住宅に特化しており、価格帯を広げる規格商品が無いとみられる | K12: https://www.e-mansion.co.jp/bbs/thread/10070/ | M12: 未着手
A13: 12 | B13: C | C13: 神奈川県 | D13: 小田原市 | E13: 株式会社江原工務店 | G13: 小田原拠点の木造注文住宅の販売・設計・施工、リフォーム・増改築 | J13: 県西部の木造注文工務店で、規格・高性能を売りにした商品が確認できない | K13: https://compalyze.co.jp/company/4021001034816 | M13: 未着手
A14: 13 | B14: C | C14: 神奈川県 | D14: 小田原市 | E14: 有限会社片山工務店 | G14: 昭和55年創業。小田原市内を中心に木造注文住宅 | J14: 小規模の木造注文工務店で、新規集客用の商品を持っていない | K14: https://www.seikatsu-guide.com/info/14/14206/7/ | M14: 未着手
A15: 14 | B15: C | C15: 神奈川県 | D15: 川崎市 | E15: 有限会社太洋建設 | G15: 昭和33年に田中工務店として開業。地域密着の在来木造住宅 | J15: 在来木造の老舗で、規格・高性能の商品が無いとみられる | K15: https://crexgroup.com/ja/home-building/region/kawasaki-city-construction-company-ranking-selection/ | M15: 未着手
A16: 15 | B16: C | C16: 神奈川県 | D16: 横浜市旭区 | E16: 有限会社大内工務店 | G16: 55年以上の地域工務店。自社大工による在来木造住宅、共同住宅、店舗、リフォーム | J16: 自社大工の施工力はあるが、商品・集客の仕組みが見えない | K16: https://itp.ne.jp/zenkoku/kanagawa/yokohamashi-kanagawaku/sammaichiyo/146465800200000899 | M16: 未着手
A17: 16 | B17: C | C17: 神奈川県 | D17: 相模原市 | E17: ギミックデザイン | G17: 「デザイン×性能×コスト」を掲げる設計事務所兼工務店。建築家が設計から現場まで一貫して担当 | J17: デザインとコストを重視する方針が、LIFE Xのデザイン規格住宅と重なる | K17: https://crexgroup.com/ja/home-building/region/sagamihara-construction-company-list/ | M17: 未着手
A18: 17 | B18: C | C18: 神奈川県 | D18: 茅ヶ崎市 | E18: 株式会社湘南渡辺 | G18: 1949年創業の一級建築士事務所。設計・新築・リフォーム・不動産 | J18: 設計と不動産の両方を持っており、規格住宅を加えれば土地とセットで売る導線が作れる | K18: https://www.e-mansion.co.jp/bbs/thread/673787/ | M18: 未着手
A19: 18 | B19: A | C19: 千葉県 | D19: 八街市 | E19: 株式会社工藤工務店 | G19: 1981年創業。FPウレタン断熱パネルの「FPの家」（UA値0.46以下・C値0.5以下）、自社大工施工 | H19: 累計700棟以上 | I19: FPの家（FPグループ工法ネットワーク）採用 | J19: 自社大工の中規模工務店でFPの高単価注文が主体のため、低価格の規格ラインを追加できる | K19: https://compalyze.co.jp/company/7011501006180 ; https://news.mynavi.jp/real-estate-assessment/73482 | M19: 未着手
A20: 19 | B20: A | C20: 千葉県 | D20: 市川市 | E20: 株式会社ダイシュウ | F20: https://www.daishu.co.jp/ | G20: 創業37年の工務店・一級建築士事務所。無垢材・漆喰で高耐震・高断熱の注文住宅（市川・松戸・船橋） | H20: 累計建築実績3,011棟（自社表記） | J20: 自然素材の高単価注文が主体で、1,000万円台の規格住宅を加えれば一次取得層の取りこぼしを拾える | K20: https://www.daishu.co.jp/workarea/%E8%88%B9%E6%A9%8B%E5%B8%82/ | M20: 未着手
A21: 20 | B21: B | C21: 千葉県 | E21: ウェルカムホーム | F21: https://www.welcome-home.jp/ | G21: 創業30年。デザイン注文住宅・高性能住宅。船橋・習志野・市川の一部・八千代が対応エリア | J21: デザインと高性能を打ち出す方向性がLIFE Xと合い、規格版を追加する余地がある | K21: https://www.welcome-home.jp/funabasi/ | M21: 未着手
A22: 21 | B22: B | C22: 千葉県 | D22: 八千代市 | E22: 木のすまい工房 | G22: 2010年創業の木の注文住宅 | H22: 2022年施工実績40棟 | J22: 年40棟の中規模で伸びている会社であり、規格商品を加えればさらに伸ばせる | K22: https://akitekt.net/koumutenmatome-1-27/ | M22: 未着手
A23: 22 | B23: B | C23: 千葉県 | D23: 千葉市 | E23: 創建住販 | G23: 平成元年に千葉市で開業した注文住宅会社。千葉市・市原市・四街道市が対応エリア | H23: 累計引き渡し2,000棟以上、年間約80棟以上 | J23: 棟数規模が対象帯の上位にあり、高性能な規格商品を加えれば商品の幅を広げられる | K23: https://news.mynavi.jp/real-estate-assessment/73482 | M23: 未着手
A24: 23 | B24: B | C24: 千葉県 | D24: 千葉市 | E24: 秋葉工務店 | G24: エアコン1台で快適な高断熱住宅 | H24: 創業20年で施工実績200棟超（年平均約10棟と算出） | J24: 小〜中規模の高断熱工務店で、規格商品を加えれば棟数を伸ばせる | K24: https://news.mynavi.jp/real-estate-assessment/73482 | M24: 未着手
A25: 24 | B25: B | C25: 千葉県 | D25: 千葉市稲毛区 | E25: 秋田建設工業株式会社 | G25: 1970年設立。木造2×4住宅が主力、自社設計・自社施工。大規模木造ホテル・店舗なども | H25: 従業員25名、資本金1億円、最近の年間完成棟数100棟超（求人情報） | J25: 2×4の自社施工体制が整っているので、規格住宅を加えれば受注効率を上げられる | K25: https://en-ambi.com/job/j-5351318/ | M25: 未着手
A26: 25 | B26: B | C26: 千葉県 | D26: 成田市 | E26: ヒラヤマホーム株式会社 | G26: 1901年木材業創業の老舗。注文住宅・リフォーム。コミコミ価格の「ファミールWX」プラン | J26: コミコミの規格的プランは既にあるため、性能（断熱等級6・太陽光標準）での差し替えを提案できる | K26: https://www.value-press.com/pressrelease/159201 ; https://www.biz.ne.jp/company/manahome/ | M26: 未着手
A27: 26 | B27: B | C27: 千葉県 | D27: 旭市 | E27: 有限会社丸富士工務店 | G27: 創業50年。営業専任を置かず専属担当が設計・施工監理・アフターまで担う自社責任施工 | J27: 営業担当がおらず集客力が弱いとみられ、FCの集客支援と規格商品が効く | K27: https://tsukulink.net/chiba/city_121011/254263 | M27: 未着手
A28: 27 | B28: B | C28: 千葉県 | D28: 船橋市 | E28: 株式会社本間工務店 | G28: ヒアリングから設計・施工までワンストップの注文住宅。高断熱・独自保証・設計力 | H28: 施工経験300棟以上 | J28: 設計力を売りにした注文住宅が中心で、規格商品の情報が無い | K28: https://funabashi.mypl.net/article/kurashi_funabashi/86372 ; https://honma-ltd.jp/media/chibakenn/ | M28: 未着手
A29: 28 | B29: B | C29: 千葉県 | D29: 茂原市 | E29: 協和ハウジング | F29: https://www.kyowa-housing.co.jp/ | G29: 1977年創業。茂原本社・東金支店の地域密着注文住宅 | J29: 外房エリアの地場ビルダーで、大手やローコスト系と競う中で高性能規格住宅が武器になる | K29: https://www.kyowa-housing.co.jp/ | M29: 未着手
A30: 29 | B30: C | C30: 千葉県 | D30: 佐倉市 | E30: さくら住建 | G30: 44年の歴史。「家族がずっとつながる家」を掲げる注文住宅 | J30: 地域密着の注文工務店で、商品ラインの拡充余地がある | K30: https://www.houzz.jp/professionals/general-contractor/%E4%BD%90%E5%80%89%E5%B8%82-04-jp-probr0-bo~t_16120~r_2111215 | M30: 未着手
A31: 30 | B31: C | C31: 千葉県 | D31: 八千代市 | E31: 木ここち家ラボ（オカムラホーム） | G31: 1995年創業の木の注文住宅 | J31: 地域の木造注文工務店で、規格・ローコスト帯の商品が確認できない | K31: https://akitekt.net/koumutenmatome-1-27/ | M31: 未着手
A32: 31 | B32: C | C32: 千葉県 | D32: 君津市 | E32: 株式会社君津住宅 | G32: 1990年設立。高品質・低価格の注文住宅。木更津・君津・茂原に展示場、完全反響型営業 | H32: 従業員250名（doda） | J32: 規模が対象帯を超え、低価格商品も既に持っているため適合度は低い | K32: https://doda.jp/DodaFront/View/CompanyJobs/j_id__10005586452/ | M32: 未着手
A33: 32 | B33: C | C33: 千葉県 | D33: 柏市 | E33: 株式会社グリーンホーム | G33: 建築・不動産の総合サービス。新築は完全自由設計 | J33: 完全自由設計が主体で、不動産の顧客向けに規格住宅を売る導線が作れる | K33: https://crexgroup.com/ja/home-building/region/kashiwa-city-builder-ranking/ | M33: 未着手
A34: 33 | B34: C | C34: 千葉県 | D34: 流山市 | E34: 有限会社綱木工業（ハウジングツナキ） | G34: 耐震補強・新築・リフォーム。流山・我孫子・松戸・柏が対応エリア | J34: 耐震・リフォーム中心で、新築の集客商品として規格住宅を導入する余地がある | K34: https://www.biz.ne.jp/corporation/29241/ | M34: 未着手
A35: 34 | B35: C | C35: 千葉県 | D35: 船橋市 | E35: 株式会社フジ設計企画 | G35: 1984年創業。地域密着の工務店でアフターフォローに注力 | J35: 地域密着の中小工務店で、商品力・集客を強化する余地がある | K35: https://funabashi.mypl.net/article/kurashi_funabashi/86372 | M35: 未着手
A36: 35 | B36: C | C36: 千葉県 | D36: 船橋市 | E36: 日動建設株式会社 | G36: 創業40年以上。大工施工の木造住宅にこだわる地元工務店 | J36: 職人型の木造工務店で規格商品が無く、集客商品が必要とみられる | K36: https://funabashi.mypl.net/article/kurashi_funabashi/86372 | M36: 未着手
A37: 36 | B37: A | C37: 静岡県 | D37: 掛川市 | E37: 有限会社大忠工務店 | G37: 1979年創業。掛川中心に西部・中遠で木造注文住宅、リフォーム、寺社建築。企画にない自由設計が強み | J37: 「企画にない自由設計」を掲げる小規模工務店で規格商品が無く、若年層向けの低価格高性能商品で受注層を広げられる。 | K37: https://compalyze.co.jp/company/4080402018059 | M37: 未着手
A38: 37 | B38: A | C38: 静岡県 | D38: 沼津市 | E38: 株式会社芹工務店 | G38: 沼津で30年以上の地域密着工務店。新築注文住宅＋リフォーム、地元材の富士ひのき使用・デザインと性能の両立 | J38: 注文住宅一本で規格・価格訴求商品が見当たらず、富士ひのきの性能訴求と組み合わせた入口商品として規格住宅を提案しやすい。 | K38: https://en-gage.net/serikosaiyo_saiyo/work_17700223/ | M38: 未着手
A39: 38 | B39: B | C39: 静岡県 | E39: 有限会社富士ホームズデザイン | G39: 一級建築士事務所兼工務店。自由設計注文住宅中心（平屋・二世帯・店舗併用）、耐震等級3・制震・長期優良・断熱等級5以上標準 | J39: 性能仕様が近いので、規格化された断熱等級6・太陽光標準の商品へ移りやすく、口コミ評価がまちまちなため集客面の支援も効きそう。 | K39: https://www.e-mansion.co.jp/bbs/thread/212986/ | M39: 未着手
A40: 39 | B40: B | C40: 静岡県 | E40: 株式会社アオイ建築 | G40: ブランド「Hands Works」。新築・リフォーム・不動産、店舗併用住宅・美容室も対応。富士宮・富士・裾野で施工 | J40: デザイン系の自由設計が中心で、価格帯の低い規格ラインを追加する余地がある。 | K40: https://compalyze.co.jp/company/2080101011812 | M40: 未着手
...

Sheet サマリー
A1: LIFE X 加盟店開拓 アタックリスト サマリー
A2: 数値はすべて『アタックリスト』シートから数式で自動集計されます。
A4: 都道府県 | B4: A | C4: B | D4: C | E4: 合計 | F4: 接触済 | G4: 商談中以上 | H4: 加盟決定
A5: 神奈川県 | B5: =COUNTIFS(アタックリスト!$C$2:$C$305,$A5,アタックリスト!$B$2:$B$305,"A") -> 3 | C5: =COUNTIFS(アタックリスト!$C$2:$C$305,$A5,アタックリスト!$B$2:$B$305,"B") -> 4 | D5: =COUNTIFS(アタックリスト!$C$2:$C$305,$A5,アタックリスト!$B$2:$B$305,"C") -> 10 | E5: =SUM(B5:D5) -> 17 | F5: =COUNTIFS(アタックリスト!$C$2:$C$305,$A5,アタックリスト!$M$2:$M$305,"<>未着手",アタックリスト!$M$2:$M$305,"<>") -> 0 | G5: =COUNTIFS(アタックリスト!$C$2:$C$305,$A5,アタックリスト!$M$2:$M$305,"商談中")+COUNTIFS(アタックリスト!$C$2:$C$305,$A5,アタックリスト!$M$2:$M$305,"セミナー参加")+COUNTIFS(アタックリスト!$C$2:$C$305,$A5,アタックリスト!$M$2:$M$305,"検討中")+COUNTIFS(アタックリスト!$C$2:$C$305,$A5,アタックリスト!$M$2:$M$305,"加盟決定") -> 0 | H5: =COUNTIFS(アタックリスト!$C$2:$C$305,$A5,アタックリスト!$M$2:$M$305,"加盟決定") -> 0
A6: 千葉県 | B6: =COUNTIFS(アタックリスト!$C$2:$C$305,$A6,アタックリスト!$B$2:$B$305,"A") -> 2 | C6: =COUNTIFS(アタックリスト!$C$2:$C$305,$A6,アタックリスト!$B$2:$B$305,"B") -> 9 | D6: =COUNTIFS(アタックリスト!$C$2:$C$305,$A6,アタックリスト!$B$2:$B$305,"C") -> 7 | E6: =SUM(B6:D6) -> 18 | F6: =COUNTIFS(アタックリスト!$C$2:$C$305,$A6,アタックリスト!$M$2:$M$305,"<>未着手",アタックリスト!$M$2:$M$305,"<>") -> 0 | G6: =COUNTIFS(アタックリスト!$C$2:$C$305,$A6,アタックリスト!$M$2:$M$305,"商談中")+COUNTIFS(アタックリスト!$C$2:$C$305,$A6,アタックリスト!$M$2:$M$305,"セミナー参加")+COUNTIFS(アタックリスト!$C$2:$C$305,$A6,アタックリスト!$M$2:$M$305,"検討中")+COUNTIFS(アタックリスト!$C$2:$C$305,$A6,アタックリスト!$M$2:$M$305,"加盟決定") -> 0 | H6: =COUNTIFS(アタックリスト!$C$2:$C$305,$A6,アタックリスト!$M$2:$M$305,"加盟決定") -> 0
A7: 静岡県 | B7: =COUNTIFS(アタックリスト!$C$2:$C$305,$A7,アタックリスト!$B$2:$B$305,"A") -> 2 | C7: =COUNTIFS(アタックリスト!$C$2:$C$305,$A7,アタックリスト!$B$2:$B$305,"B") -> 12 | D7: =COUNTIFS(アタックリスト!$C$2:$C$305,$A7,アタックリスト!$B$2:$B$305,"C") -> 5 | E7: =SUM(B7:D7) -> 19 | F7: =COUNTIFS(アタックリスト!$C$2:$C$305,$A7,アタックリスト!$M$2:$M$305,"<>未着手",アタックリスト!$M$2:$M$305,"<>") -> 0 | G7: =COUNTIFS(アタックリスト!$C$2:$C$305,$A7,アタックリスト!$M$2:$M$305,"商談中")+COUNTIFS(アタックリスト!$C$2:$C$305,$A7,アタックリスト!$M$2:$M$305,"セミナー参加")+COUNTIFS(アタックリスト!$C$2:$C$305,$A7,アタックリスト!$M$2:$M$305,"検討中")+COUNTIFS(アタックリスト!$C$2:$C$305,$A7,アタックリスト!$M$2:$M$305,"加盟決定") -> 0 | H7: =COUNTIFS(アタックリスト!$C$2:$C$305,$A7,アタックリスト!$M$2:$M$305,"加盟決定") -> 0
A8: 愛知県 | B8: =COUNTIFS(アタックリスト!$C$2:$C$305,$A8,アタックリスト!$B$2:$B$305,"A") -> 2 | C8: =COUNTIFS(アタックリスト!$C$2:$C$305,$A8,アタックリスト!$B$2:$B$305,"B") -> 6 | D8: =COUNTIFS(アタックリスト!$C$2:$C$305,$A8,アタックリスト!$B$2:$B$305,"C") -> 8 | E8: =SUM(B8:D8) -> 16 | F8: =COUNTIFS(アタックリスト!$C$2:$C$305,$A8,アタックリスト!$M$2:$M$305,"<>未着手",アタックリスト!$M$2:$M$305,"<>") -> 0 | G8: =COUNTIFS(アタックリスト!$C$2:$C$305,$A8,アタックリスト!$M$2:$M$305,"商談中")+COUNTIFS(アタックリスト!$C$2:$C$305,$A8,アタックリスト!$M$2:$M$305,"セミナー参加")+COUNTIFS(アタックリスト!$C$2:$C$305,$A8,アタックリスト!$M$2:$M$305,"検討中")+COUNTIFS(アタックリスト!$C$2:$C$305,$A8,アタックリスト!$M$2:$M$305,"加盟決定") -> 0 | H8: =COUNTIFS(アタックリスト!$C$2:$C$305,$A8,アタックリスト!$M$2:$M$305,"加盟決定") -> 0
A9: 石川県 | B9: =COUNTIFS(アタックリスト!$C$2:$C$305,$A9,アタックリスト!$B$2:$B$305,"A") -> 2 | C9: =COUNTIFS(アタックリスト!$C$2:$C$305,$A9,アタックリスト!$B$2:$B$305,"B") -> 7 | D9: =COUNTIFS(アタックリスト!$C$2:$C$305,$A9,アタックリスト!$B$2:$B$305,"C") -> 7 | E9: =SUM(B9:D9) -> 16 | F9: =COUNTIFS(アタックリスト!$C$2:$C$305,$A9,アタックリスト!$M$2:$M$305,"<>未着手",アタックリスト!$M$2:$M$305,"<>") -> 0 | G9: =COUNTIFS(アタックリスト!$C$2:$C$305,$A9,アタックリスト!$M$2:$M$305,"商談中")+COUNTIFS(アタックリスト!$C$2:$C$305,$A9,アタックリスト!$M$2:$M$305,"セミナー参加")+COUNTIFS(アタックリスト!$C$2:$C$305,$A9,アタックリスト!$M$2:$M$305,"検討中")+COUNTIFS(アタックリスト!$C$2:$C$305,$A9,アタックリスト!$M$2:$M$305,"加盟決定") -> 0 | H9: =COUNTIFS(アタックリスト!$C$2:$C$305,$A9,アタックリスト!$M$2:$M$305,"加盟決定") -> 0
A10: 香川県 | B10: =COUNTIFS(アタックリスト!$C$2:$C$305,$A10,アタックリスト!$B$2:$B$305,"A") -> 3 | C10: =COUNTIFS(アタックリスト!$C$2:$C$305,$A10,アタックリスト!$B$2:$B$305,"B") -> 9 | D10: =COUNTIFS(アタックリスト!$C$2:$C$305,$A10,アタックリスト!$B$2:$B$305,"C") -> 6 | E10: =SUM(B10:D10) -> 18 | F10: =COUNTIFS(アタックリスト!$C$2:$C$305,$A10,アタックリスト!$M$2:$M$305,"<>未着手",アタックリスト!$M$2:$M$305,"<>") -> 0 | G10: =COUNTIFS(アタックリスト!$C$2:$C$305,$A10,アタックリスト!$M$2:$M$305,"商談中")+COUNTIFS(アタックリスト!$C$2:$C$305,$A10,アタックリスト!$M$2:$M$305,"セミナー参加")+COUNTIFS(アタックリスト!$C$2:$C$305,$A10,アタックリスト!$M$2:$M$305,"検討中")+COUNTIFS(アタックリスト!$C$2:$C$305,$A10,アタックリスト!$M$2:$M$305,"加盟決定") -> 0 | H10: =COUNTIFS(アタックリスト!$C$2:$C$305,$A10,アタックリスト!$M$2:$M$305,"加盟決定") -> 0
A11: 合計 | B11: =SUM(B5:B10) -> 14 | C11: =SUM(C5:C10) -> 47 | D11: =SUM(D5:D10) -> 43 | E11: =SUM(E5:E10) -> 104 | F11: =SUM(F5:F10) -> 0 | G11: =SUM(G5:G10) -> 0 | H11: =SUM(H5:H10) -> 0
A13: ステータス別
A14: 未着手 | B14: =COUNTIF(アタックリスト!$M$2:$M$305,A14) -> 104
A15: 資料送付 | B15: =COUNTIF(アタックリスト!$M$2:$M$305,A15) -> 0
A16: アポ獲得 | B16: =COUNTIF(アタックリスト!$M$2:$M$305,A16) -> 0
A17: 商談中 | B17: =COUNTIF(アタックリスト!$M$2:$M$305,A17) -> 0
A18: セミナー参加 | B18: =COUNTIF(アタックリスト!$M$2:$M$305,A18) -> 0
A19: 検討中 | B19: =COUNTIF(アタックリスト!$M$2:$M$305,A19) -> 0
A20: 加盟決定 | B20: =COUNTIF(アタックリスト!$M$2:$M$305,A20) -> 0
A21: 見送り | B21: =COUNTIF(アタックリスト!$M$2:$M$305,A21) -> 0
A22: 対象外 | B22: =COUNTIF(アタックリスト!$M$2:$M$305,A22) -> 0
A24: 2026年12月末 全国50社目標（PR TIMES発表）に対する重点6県からの加盟決定数 | H24: =H11 -> 0

Sheet LIFE X概要・トーク
A1: ■ LIFE X 概要（公開情報ベース）
A2: 運営 | B2: 株式会社Gハウス（大阪）
A3: 開始 | B3: 2026年4月1日。開始2ヶ月で加盟15社突破、施主からの問い合わせ300件以上
A4: 目標 | B4: 2026年12月末までに全国50社
A5: 料金体系 | B5: 棟数に応じたロイヤリティなし。加盟金＋月会費のみ（金額は公開情報では未確認）
A6: 重点募集エリア | B6: 神奈川・千葉・静岡・愛知・石川・香川（いずれも既存加盟店なし）
A7: 価格 | B7: 本体1,890万円〜（税込2,079万円）、坪単価60万円前後
A8: プラン | B8: 平屋・2階建て 70プラン以上（有名建築家プランも予定）
A9: 性能 | B9: 耐震等級3（許容応力度計算）・制振ダンパー／断熱等級6（UA値0.46）／C値0.24／第一種全熱交換換気／太陽光標準（最大11.16kW）／省令準耐火
A10: 設備 | B10: GRAFTEKTキッチン、BOSCH食洗機 など
A11: 集客支援 | B11: GハウスのWeb集客ノウハウを加盟店エリアに展開（Gハウス実績：昨年対比約140%超）
A13: ■ 競合FCの費用水準（比較メディア等の2次情報。商談前に最新情報を確認）
A14: アイフルホーム | B14: 加盟金400万円（税別）／月額固定30万円＋延床1㎡あたり1,700〜2,200円／約380エリア完全テリトリー制
A15: R+house | B15: 加盟金500万円前後／契約1棟ごとにロイヤリティ
A16: ジブンハウス | B16: 費用非公開／store型は1エリア1店舗、instore型は店舗数制限なし
A17: 業界相場 | B17: 加盟金200〜500万円、月額20〜30万円＋棟数課金が一般的
A19: ■ 刺さるトーク（タイプ別）
A20: 注文住宅のみの工務店 | B20: 「高単価の注文住宅は残したまま、2,000万円前後の一次取得層向けの商品を、開発費ゼロで追加できます」
A21: 棟数を伸ばしたいビルダー | B21: 「棟数が増えてもロイヤリティは増えません。売れるほど利益が残る仕組みです」
A22: 他FC加盟済みの工務店 | B22: 「今のFCと併用しやすい月会費制です。棟数課金のFCと比べて、総コストを試算してみませんか」
A23: 集客に悩む工務店 | B23: 「Gハウスで成果が出たWeb集客の型を、エリアにそのまま展開します。開始2ヶ月で問い合わせ300件以上です」
A24: 高性能住宅を作りたい工務店 | B24: 「等級3・断熱等級6・C値0.24・太陽光標準の仕様を、規格化した価格で出せます」
A25: 石川県（能登復興） | B25: 「耐震等級3＋制振の規格住宅なら、再建需要に短い工期・明確な価格で応えられます」
A27: ■ 出典
A28: PR TIMES | B28: https://prtimes.jp/main/html/rd/p/000000060.000159579.html
A29: PR TIMES | B29: https://prtimes.jp/main/html/rd/p/000000053.000159579.html
A30: 公式 | B30: https://lifex-house.jp/

Sheet 除外_既存加盟店
A1: 地域 | B1: 都道府県 | C1: 社名（LIFE X加盟済み）
A2: 東北 | B2: 岩手県 | C2: シリウス
A3: 東北 | B3: 福島県 | C3: スピークス
A4: 関東 | B4: 栃木県 | C4: Life&Design
A5: 関東 | B5: 埼玉県・東京都 | C5: YUNO HOME
A6: 中部 | B6: 新潟県 | C6: ダイケンアーキテクツ／大建建設
A7: 近畿 | B7: 奈良県 | C7: 竹村工務店
A8: 近畿 | B8: 奈良県 | C8: キノシタ
A9: 近畿 | B9: 大阪府 | C9: いえプロ不動産
A10: 中国 | B10: 島根県・鳥取県 | C10: 中央建設
A11: 中国 | B11: 広島県 | C11: 坂本建設工業
A12: 中国 | B12: 広島県 | C12: フラワーホーム／BJC
... A15: 不明 | B15: 未確認 | C15: 建匠
A17: 出典：lifex-house.jp/partner/（検索結果の内容から作成。最新の一覧は公式ページで確認してください）
